<robot name="oxpa_magnet" version="1.0">
  <joint name="gripper_joint" type="fixed">
    <origin rpy="0.00000 0.00000 0.00000" xyz="0.00192 0.00000 -0.09046"/>
    <parent link="base_link"/>
    <child link="gripper_link"/>
  </joint>
  <joint name="rotor_0" type="revolute">
    <limit lower="-3.14000" upper="3.14000" effort="0.00000" velocity="0.00000"/>
    <origin rpy="0.00000 0.00000 0.00000" xyz="0.17281 -0.17000 0.04217"/>
    <parent link="base_link"/>
    <child link="rotor_0_link"/>
    <axis xyz="0.00000 0.00000 1.00000"/>
  </joint>
  <joint name="rotor_1" type="revolute">
    <limit lower="-3.14000" upper="3.14000" effort="0.00000" velocity="0.00000"/>
    <origin rpy="0.00000 0.00000 0.00000" xyz="-0.16699 0.17000 0.04217"/>
    <parent link="base_link"/>
    <child link="rotor_1_link"/>
    <axis xyz="0.00000 0.00000 1.00000"/>
  </joint>
  <joint name="rotor_2" type="revolute">
    <limit lower="-3.14000" upper="3.14000" effort="0.00000" velocity="0.00000"/>
    <origin rpy="0.00000 0.00000 0.00000" xyz="0.17301 0.17000 0.04217"/>
    <parent link="base_link"/>
    <child link="rotor_2_link"/>
    <axis xyz="0.00000 0.00000 1.00000"/>
  </joint>
  <joint name="rotor_3" type="revolute">
    <limit lower="-3.14000" upper="3.14000" effort="0.00000" velocity="0.00000"/>
    <origin rpy="0.00000 0.00000 0.00000" xyz="-0.16699 -0.17000 0.04217"/>
    <parent link="base_link"/>
    <child link="rotor_3_link"/>
    <axis xyz="0.00000 0.00000 1.00000"/>
  </joint>
  
  <link name="base_link">
    <inertial>
      <inertia ixx="0.00100" ixy="0.00000" ixz="0.00000" iyy="0.00100" iyz="0.00000" izz="0.00100"/>
      <origin rpy="0.00000 0.00000 0.00000" xyz="0.005843 0.00060 0.07404"/>
      <mass value="1.98000"/>
    </inertial>
    <visual name="body">
      <origin rpy="0.00000 0.00000 0.00000" xyz="0.00584 0.00060 -0.01846"/>
      <material name="oxpa"/>
      <geometry>
        <mesh filename="./oxpa_meshes/dae/body.dae" scale="1.00000 1.00000 1.00000"/>
      </geometry>
    </visual>
    <collision name= "body_collision">
      <origin rpy="0.00000 0.00000 0.00000" xyz="0.00000 0.00000 0.0000"/>
      <geometry>
        <box size="0.388 0.388 0.1800"/>
      </geometry>
    </collision>
  </link>
  <link name="gripper_link">
    <visual name="gripper_plate">
      <origin rpy="0.00000 0.00000 0.00000" xyz="0.00000 0.00000 0.00000"/>
      <material name="acrylic"/>
      <geometry>
        <mesh filename="./oxpa_meshes/dae/plate.dae" scale="1.00000 1.00000 1.00000"/>
      </geometry>
    </visual>
  </link>
  <link name="rotor_0_link">
    <inertial>
      <inertia ixx="0.00009" ixy="0.00000" ixz="0.00000" iyy="0.00009" iyz="0.00000" izz="0.00018"/>
      <origin rpy="0.00000 0.00000 0.00000" xyz="0.00001 0.00006 -0.00033"/>
      <mass value="0.01100"/>
    </inertial>
    <visual name="rotor_0">
      <origin rpy="-0.00000 0.00000 -0.00000" xyz="0.00000 0.00000 0.00000"/>
      <material name="prop"/>
      <geometry>
        <mesh filename="./oxpa_meshes/dae/rotor0.dae" scale="1.00000 1.00000 1.00000"/>
      </geometry>
    </visual>
    <collision>
      <origin rpy="0.00000 0.00000 0.00000" xyz="0.00000 0.00000 0.00000"/>
      <geometry>
        <cylinder length="0.006" radius="0.127"/>
      </geometry>
    </collision>
  </link>
  <link name="rotor_1_link">
    <inertial>
      <inertia ixx="0.00009" ixy="0.00000" ixz="0.00000" iyy="0.00009" iyz="0.00000" izz="0.00018"/>
      <origin rpy="0.00000 0.00000 0.00000" xyz="0.00003 0.00005 -0.00035"/>
      <mass value="0.01100"/>
    </inertial>
    <visual name="rotor_1">
      <origin rpy="-0.00000 0.00000 -0.00000" xyz="0.00000 0.00000 0.00000"/>
      <material name="prop"/>
      <geometry>
        <mesh filename="./oxpa_meshes/dae/rotor1.dae" scale="1.00000 1.00000 1.00000"/>
      </geometry>
    </visual>
    <collision>
      <origin rpy="0.00000 0.00000 0.00000" xyz="0.00000 -0.00000 0.00000"/>
      <geometry>
        <cylinder length="0.006" radius="0.127"/>
      </geometry>
    </collision>
  </link>
  <link name="rotor_2_link">
    <inertial>
      <inertia ixx="0.00009" ixy="0.00000" ixz="0.00000" iyy="0.00009" iyz="0.00000" izz="0.00018"/>
      <origin rpy="0.00000 0.00000 0.00000" xyz="-0.00014 -0.00013 0.00035"/>
      <mass value="0.01100"/>
    </inertial>
    <visual name="rotor_2">
      <origin rpy="0.00000 0.00000 0.00000" xyz="0.00000 0.00000 0.00000"/>
      <material name="prop"/>
      <geometry>
        <mesh filename="./oxpa_meshes/dae/rotor2.dae" scale="1.00000 1.00000 1.00000"/>
      </geometry>
    </visual>
    <collision>
      <origin rpy="0.00000 0.00000 0.00000" xyz="0.00000 -0.00000 0.00000"/>
      <geometry>
        <cylinder length="0.006" radius="0.127"/>
      </geometry>
    </collision>
  </link>
  <link name="rotor_3_link">
    <inertial>
      <inertia ixx="0.00009" ixy="0.00000" ixz="0.00000" iyy="0.00009" iyz="0.00000" izz="0.00018"/>
      <origin rpy="0.00000 0.00000 0.00000" xyz="-0.00004 0.00061 0.00036"/>
      <mass value="0.01100"/>
    </inertial>
    <visual name="rotor_3">
      <origin rpy="0.00000 0.00000 0.00000" xyz="0.00000 0.00000 0.00000"/>
      <material name="prop"/>
      <geometry>
        <mesh filename="./oxpa_meshes/dae/rotor3.dae" scale="1.00000 1.00000 1.00000"/>
      </geometry>
    </visual>
    <collision>
      <origin rpy="0.00000 0.00000 0.00000" xyz="0.00000 -0.00000 0.00000"/>
      <geometry>
        <cylinder length="0.006" radius="0.127"/>
      </geometry>
    </collision>
  </link>
  
  <material name="acrylic">
    <color rgba="0.80000 0.80000 0.80000 1.00000"/>
  </material>
  <material name="oxpa">
    <texture filename="./oxpa_meshes/dae/oxpa_albedo.png"/>
    <color rgba="0.80000 0.80000 0.80000 1.00000"/>
  </material>
</robot>
